Workbook

Sheet Сводка
A1: Сводка по промокодам Flexy Way
A2: Контроль выпуска кодов по уровням и категориям. Все показатели рассчитываются из справочника и реестра.
A4: Всего призов | C4: Всего промокодов | E4: Дубликатов | G4: Ошибок по количеству
A5: =COUNTA('Справочник призов'!$A$5:$A$17) | C5: =COUNTA('Промокоды'!$F$5:$F$2407) | E5: =COUNTIF('Промокоды'!$L$5:$L$2407,"Дубликат") | G5: =COUNTIF('Справочник призов'!$K$5:$K$17,"Ошибка")
A8: Уровень | B8: Количество призов | C8: Промокодов | E8: Категория | F8: Количество призов | G8: Промокодов
A9: 1 уровень | B9: =COUNTIF('Справочник призов'!$C$5:$C$17,A9) | C9: =COUNTIF('Промокоды'!$B$5:$B$2407,A9) | E9: Закрытые условия на абонементы | F9: =COUNTIF('Справочник призов'!$B$5:$B$17,E9) | G9: =COUNTIF('Промокоды'!$C$5:$C$2407,E9)
A10: 2 уровень | B10: =COUNTIF('Справочник призов'!$C$5:$C$17,A10) | C10: =COUNTIF('Промокоды'!$B$5:$B$2407,A10) | E10: Призы не на абонементы | F10: =COUNTIF('Справочник призов'!$B$5:$B$17,E10) | G10: =COUNTIF('Промокоды'!$C$5:$C$2407,E10)
A11: 3 уровень | B11: =COUNTIF('Справочник призов'!$C$5:$C$17,A11) | C11: =COUNTIF('Промокоды'!$B$5:$B$2407,A11) | E11: Суперприз | F11: =COUNTIF('Справочник призов'!$B$5:$B$17,E11) | G11: =COUNTIF('Промокоды'!$C$5:$C$2407,E11)
A12: Суперприз | B12: =COUNTIF('Справочник призов'!$C$5:$C$17,A12) | C12: =COUNTIF('Промокоды'!$B$5:$B$2407,A12) | E12: Итого | F12: =SUM(F9:F11) | G12: =SUM(G9:G11)
A13: Итого | B13: =SUM(B9:B12) | C13: =SUM(C9:C12)
A15: Как пользоваться файлом
A16: • Основной рабочий лист — «Промокоды». В колонке «Статус» доступен список: Не использован / Использован / Аннулирован.
A17: • В случайной части кодов используются латинские заглавные буквы и цифры без неоднозначных символов 0, O, 1 и I; префикс L1/L2/L3 показывает уровень.
A18: • Для суперприза сформировано 3 кода; каждый код дает один бесплатный абонемент на 8 занятий.
A19: • Для «Парного старта» размер закрытой цены не был указан — его нужно определить до применения промокодов.

Sheet Справочник призов
A1: Справочник призов
A2: Все призы, условия и плановое количество кодов. Колонки «Сгенерировано» и «Контроль» рассчитываются по реестру промокодов.
A4: Код приза | B4: Категория | C4: Уровень | D4: Приз | E4: Механика | F4: Скидка | G4: Условия применения | H4: Примечание | I4: План кодов | J4: Сгенерировано | K4: Контроль
A5: SUB-L1-04-10 | B5: Закрытые условия на абонементы | C5: 1 уровень | D5: Скидка 10% на абонемент 4 занятия | E5: Скидка | F5: 0.1 | G5: При покупке абонемента на 4 занятия | I5: 200 | J5: =COUNTIF('Промокоды'!$A$5:$A$2407,A5) | K5: =IF(J5=I5,"OK","Ошибка")
A6: SUB-L1-08-10 | B6: Закрытые условия на абонементы | C6: 1 уровень | D6: Скидка 10% на абонемент 8 занятий | E6: Скидка | F6: 0.1 | G6: При покупке абонемента на 8 занятий | I6: 200 | J6: =COUNTIF('Промокоды'!$A$5:$A$2407,A6) | K6: =IF(J6=I6,"OK","Ошибка")
A7: SUB-L2-08-12-15 | B7: Закрытые условия на абонементы | C7: 2 уровень | D7: Скидка 15% на абонемент 8 или 12 занятий | E7: Скидка | F7: 0.15 | G7: При покупке абонемента на 8 или 12 занятий | I7: 200 | J7: =COUNTIF('Промокоды'!$A$5:$A$2407,A7) | K7: =IF(J7=I7,"OK","Ошибка")
A8: SUB-L2-12-20 | B8: Закрытые условия на абонементы | C8: 2 уровень | D8: Скидка 20% на абонемент 12 занятий | E8: Скидка | F8: 0.2 | G8: При покупке абонемента на 12 занятий | I8: 200 | J8: =COUNTIF('Промокоды'!$A$5:$A$2407,A8) | K8: =IF(J8=I8,"OK","Ошибка")
A9: SUB-L3-12-25 | B9: Закрытые условия на абонементы | C9: 3 уровень | D9: Скидка 25% на абонемент 12 занятий | E9: Скидка | F9: 0.25 | G9: При покупке абонемента на 12 занятий | I9: 200 | J9: =COUNTIF('Промокоды'!$A$5:$A$2407,A9) | K9: =IF(J9=I9,"OK","Ошибка")
A10: SUB-L3-12-30 | B10: Закрытые условия на абонементы | C10: 3 уровень | D10: Скидка 30% на абонемент 12 занятий | E10: Скидка | F10: 0.3 | G10: При покупке абонемента на 12 занятий | I10: 200 | J10: =COUNTIF('Промокоды'!$A$5:$A$2407,A10) | K10: =IF(J10=I10,"OK","Ошибка")
A11: SUB-L3-12-40 | B11: Закрытые условия на абонементы | C11: 3 уровень | D11: Скидка 40% на абонемент 12 занятий | E11: Скидка | F11: 0.4 | G11: При покупке абонемента на 12 занятий | I11: 200 | J11: =COUNTIF('Промокоды'!$A$5:$A$2407,A11) | K11: =IF(J11=I11,"OK","Ошибка")
A12: SUPER-08-FREE | B12: Суперприз | C12: Суперприз | D12: Бесплатный абонемент на 8 занятий | E12: Бесплатный абонемент | G12: Один промокод дает один бесплатный абонемент на 8 занятий | H12: Всего выпущено 3 промокода | I12: 3 | J12: =COUNTIF('Промокоды'!$A$5:$A$2407,A12) | K12: =IF(J12=I12,"OK","Ошибка")
A13: BONUS-L1-TRIAL-3FOR2 | B13: Призы не на абонементы | C13: 1 уровень | D13: Апгрейд: 3 пробных занятия по цене 2 | E13: Апгрейд | G13: Оплата двух пробных занятий дает право посетить три | I13: 200 | J13: =COUNTIF('Промокоды'!$A$5:$A$2407,A13) | K13: =IF(J13=I13,"OK","Ошибка")
A14: BONUS-L1-PLUS7 | B14: Призы не на абонементы | C14: 1 уровень | D14: +7 дней к сроку действия абонемента | E14: Продление | G14: При покупке абонемента на 8 или 12 занятий | I14: 200 | J14: =COUNTIF('Промокоды'!$A$5:$A$2407,A14) | K14: =IF(J14=I14,"OK","Ошибка")
A15: BONUS-L1-FREEZE | B15: Призы не на абонементы | C15: 1 уровень | D15: Дополнительная заморозка абонемента | E15: Заморозка | G15: При покупке абонемента | I15: 200 | J15: =COUNTIF('Промокоды'!$A$5:$A$2407,A15) | K15: =IF(J15=I15,"OK","Ошибка")
A16: BONUS-L1-FRIEND-15 | B16: Призы не на абонементы | C16: 1 уровень | D16: Скидка 15% на второй абонемент для подруги | E16: Скидка | F16: 0.15 | G16: При покупке второго абонемента для подруги | I16: 200 | J16: =COUNTIF('Промокоды'!$A$5:$A$2407,A16) | K16: =IF(J16=I16,"OK","Ошибка")
A17: BONUS-L2-PAIR | B17: Призы не на абонементы | C17: 2 уровень | D17: Парный старт: закрытая цена на 2 абонемента | E17: Закрытая цена | G17: Покупка двух абонементов при совместном старте с подругой | H17: Размер закрытой цены в исходных условиях не указан | I17: 200 | J17: =COUNTIF('Промокоды'!$A$5:$A$2407,A17) | K17: =IF(J17=I17,"OK","Ошибка")

Sheet Промокоды
A1: Промокоды для призов игры Flexy Way
A2: 2 403 уникальных кода: по 200 для каждого обычного приза и 3 для суперприза. Обновляйте статус, дату и данные клиента по мере использования.
A4: Код приза | B4: Уровень | C4: Категория | D4: Приз | E4: Условия применения | F4: Промокод | G4: Статус | H4: Дата использования | I4: Получатель / клиент | J4: Комментарий | K4: № в пуле | L4: Контроль
A5: SUB-L1-04-10 | B5: 1 уровень | C5: Закрытые условия на абонементы | D5: Скидка 10% на абонемент 4 занятия | E5: При покупке абонемента на 4 занятия | F5: FW-L1-8LLQL-ZMXLC | G5: Использован | H5: 46249.258 | I5: Роман Михайлов, @RRedactor, +79035782777 | J5: Выдан Telegram-ботом; Роман Михайлов, @RRedactor, +79035782777; сессия: session_461c9dbf1567 | K5: 1 | L5: =IF(COUNTIF($F$5:$F$2407,F5)=1,"OK","Дубликат")
A6: SUB-L1-04-10 | B6: 1 уровень | C6: Закрытые условия на абонементы | D6: Скидка 10% на абонемент 4 занятия | E6: При покупке абонемента на 4 занятия | F6: FW-L1-TQ8VB-FWRDX | G6: Использован | H6: 46249.277 | I6: Роман Михайлов, @RRedactor, +79035782777 | J6: Выдан Telegram-ботом; Роман Михайлов, @RRedactor, +79035782777; сессия: session_9d377af4d448 | K6: 2 | L6: =IF(COUNTIF($F$5:$F$2407,F6)=1,"OK","Дубликат")
A7: SUB-L1-04-10 | B7: 1 уровень | C7: Закрытые условия на абонементы | D7: Скидка 10% на абонемент 4 занятия | E7: При покупке абонемента на 4 занятия | F7: FW-L1-VCDZQ-G894D | G7: Не использован | K7: 3 | L7: =IF(COUNTIF($F$5:$F$2407,F7)=1,"OK","Дубликат")
A8: SUB-L1-04-10 | B8: 1 уровень | C8: Закрытые условия на абонементы | D8: Скидка 10% на абонемент 4 занятия | E8: При покупке абонемента на 4 занятия | F8: FW-L1-WP3XY-L5QW6 | G8: Не использован | K8: 4 | L8: =IF(COUNTIF($F$5:$F$2407,F8)=1,"OK","Дубликат")
A9: SUB-L1-04-10 | B9: 1 уровень | C9: Закрытые условия на абонементы | D9: Скидка 10% на абонемент 4 занятия | E9: При покупке абонемента на 4 занятия | F9: FW-L1-WXCSU-KJ3QC | G9: Не использован | K9: 5 | L9: =IF(COUNTIF($F$5:$F$2407,F9)=1,"OK","Дубликат")
A10: SUB-L1-04-10 | B10: 1 уровень | C10: Закрытые условия на абонементы | D10: Скидка 10% на абонемент 4 занятия | E10: При покупке абонемента на 4 занятия | F10: FW-L1-BU5QF-U9R3H | G10: Не использован | K10: 6 | L10: =IF(COUNTIF($F$5:$F$2407,F10)=1,"OK","Дубликат")
A11: SUB-L1-04-10 | B11: 1 уровень | C11: Закрытые условия на абонементы | D11: Скидка 10% на абонемент 4 занятия | E11: При покупке абонемента на 4 занятия | F11: FW-L1-E2A4H-PEV2W | G11: Не использован | K11: 7 | L11: =IF(COUNTIF($F$5:$F$2407,F11)=1,"OK","Дубликат")
A12: SUB-L1-04-10 | B12: 1 уровень | C12: Закрытые условия на абонементы | D12: Скидка 10% на абонемент 4 занятия | E12: При покупке абонемента на 4 занятия | F12: FW-L1-8E2ZA-VLSUS | G12: Не использован | K12: 8 | L12: =IF(COUNTIF($F$5:$F$2407,F12)=1,"OK","Дубликат")
A13: SUB-L1-04-10 | B13: 1 уровень | C13: Закрытые условия на абонементы | D13: Скидка 10% на абонемент 4 занятия | E13: При покупке абонемента на 4 занятия | F13: FW-L1-JLM8C-M2ANJ | G13: Не использован | K13: 9 | L13: =IF(COUNTIF($F$5:$F$2407,F13)=1,"OK","Дубликат")
A14: SUB-L1-04-10 | B14: 1 уровень | C14: Закрытые условия на абонементы | D14: Скидка 10% на абонемент 4 занятия | E14: При покупке абонемента на 4 занятия | F14: FW-L1-NF47F-4DSZ3 | G14: Не использован | K14: 10 | L14: =IF(COUNTIF($F$5:$F$2407,F14)=1,"OK","Дубликат")
A15: SUB-L1-04-10 | B15: 1 уровень | C15: Закрытые условия на абонементы | D15: Скидка 10% на абонемент 4 занятия | E15: При покупке абонемента на 4 занятия | F15: FW-L1-G7REC-2THG4 | G15: Не использован | K15: 11 | L15: =IF(COUNTIF($F$5:$F$2407,F15)=1,"OK","Дубликат")
A16: SUB-L1-04-10 | B16: 1 уровень | C16: Закрытые условия на абонементы | D16: Скидка 10% на абонемент 4 занятия | E16: При покупке абонемента на 4 занятия | F16: FW-L1-H2RHX-ATYCV | G16: Не использован | K16: 12 | L16: =IF(COUNTIF($F$5:$F$2407,F16)=1,"OK","Дубликат")
A17: SUB-L1-04-10 | B17: 1 уровень | C17: Закрытые условия на абонементы | D17: Скидка 10% на абонемент 4 занятия | E17: При покупке абонемента на 4 занятия | F17: FW-L1-9SCLA-SD7KU | G17: Не использован | K17: 13 | L17: =IF(COUNTIF($F$5:$F$2407,F17)=1,"OK","Дубликат")
A18: SUB-L1-04-10 | B18: 1 уровень | C18: Закрытые условия на абонементы | D18: Скидка 10% на абонемент 4 занятия | E18: При покупке абонемента на 4 занятия | F18: FW-L1-2UHJ8-PFP84 | G18: Не использован | K18: 14 | L18: =IF(COUNTIF($F$5:$F$2407,F18)=1,"OK","Дубликат")
... A1607: BONUS-L1-TRIAL-3FOR2 | B1607: 1 уровень | C1607: Призы не на абонементы | D1607: Апгрейд: 3 пробных занятия по цене 2 | E1607: Оплата двух пробных занятий дает право посетить три | F1607: FW-L1-Q8UNT-H8NDS | G1607: Не использован | K1607: 200 | L1607: =IF(COUNTIF($F$5:$F$2407,F1607)=1,"OK","Дубликат")
A1608: BONUS-L1-PLUS7 | B1608: 1 уровень | C1608: Призы не на абонементы | D1608: +7 дней к сроку действия абонемента | E1608: При покупке абонемента на 8 или 12 занятий | F1608: FW-L1-72C38-M8J6W | G1608: Использован | H1608: 46249.246 | I1608: Роман Михайлов, @RRedactor, +79035782777 | J1608: Выдан Telegram-ботом; Роман Михайлов, @RRedactor, +79035782777; сессия: session_bfb6c5df5f6a | K1608: 1 | L1608: =IF(COUNTIF($F$5:$F$2407,F1608)=1,"OK","Дубликат")
A1609: BONUS-L1-PLUS7 | B1609: 1 уровень | C1609: Призы не на абонементы | D1609: +7 дней к сроку действия абонемента | E1609: При покупке абонемента на 8 или 12 занятий | F1609: FW-L1-YTS6M-JZB66 | G1609: Не использован | K1609: 2 | L1609: =IF(COUNTIF($F$5:$F$2407,F1609)=1,"OK","Дубликат")
A1610: BONUS-L1-PLUS7 | B1610: 1 уровень | C1610: Призы не на абонементы | D1610: +7 дней к сроку действия абонемента | E1610: При покупке абонемента на 8 или 12 занятий | F1610: FW-L1-C7YT4-N76EN | G1610: Не использован | K1610: 3 | L1610: =IF(COUNTIF($F$5:$F$2407,F1610)=1,"OK","Дубликат")
A1611: BONUS-L1-PLUS7 | B1611: 1 уровень | C1611: Призы не на абонементы | D1611: +7 дней к сроку действия абонемента | E1611: При покупке абонемента на 8 или 12 занятий | F1611: FW-L1-NL6LC-CXLQH | G1611: Не использован | K1611: 4 | L1611: =IF(COUNTIF($F$5:$F$2407,F1611)=1,"OK","Дубликат")
A1612: BONUS-L1-PLUS7 | B1612: 1 уровень | C1612: Призы не на абонементы | D1612: +7 дней к сроку действия абонемента | E1612: При покупке абонемента на 8 или 12 занятий | F1612: FW-L1-CH63R-KPBT2 | G1612: Не использован | K1612: 5 | L1612: =IF(COUNTIF($F$5:$F$2407,F1612)=1,"OK","Дубликат")
A1613: BONUS-L1-PLUS7 | B1613: 1 уровень | C1613: Призы не на абонементы | D1613: +7 дней к сроку действия абонемента | E1613: При покупке абонемента на 8 или 12 занятий | F1613: FW-L1-U82ZX-QWTU3 | G1613: Не использован | K1613: 6 | L1613: =IF(COUNTIF($F$5:$F$2407,F1613)=1,"OK","Дубликат")
A1614: BONUS-L1-PLUS7 | B1614: 1 уровень | C1614: Призы не на абонементы | D1614: +7 дней к сроку действия абонемента | E1614: При покупке абонемента на 8 или 12 занятий | F1614: FW-L1-8UMKM-PJ55E | G1614: Не использован | K1614: 7 | L1614: =IF(COUNTIF($F$5:$F$2407,F1614)=1,"OK","Дубликат")
A1615: BONUS-L1-PLUS7 | B1615: 1 уровень | C1615: Призы не на абонементы | D1615: +7 дней к сроку действия абонемента | E1615: При покупке абонемента на 8 или 12 занятий | F1615: FW-L1-E3HP4-WHGC7 | G1615: Не использован | K1615: 8 | L1615: =IF(COUNTIF($F$5:$F$2407,F1615)=1,"OK","Дубликат")
A1616: BONUS-L1-PLUS7 | B1616: 1 уровень | C1616: Призы не на абонементы | D1616: +7 дней к сроку действия абонемента | E1616: При покупке абонемента на 8 или 12 занятий | F1616: FW-L1-KS6M4-UCD7K | G1616: Не использован | K1616: 9 | L1616: =IF(COUNTIF($F$5:$F$2407,F1616)=1,"OK","Дубликат")
A1617: BONUS-L1-PLUS7 | B1617: 1 уровень | C1617: Призы не на абонементы | D1617: +7 дней к сроку действия абонемента | E1617: При покупке абонемента на 8 или 12 занятий | F1617: FW-L1-53RN5-4LABM | G1617: Не использован | K1617: 10 | L1617: =IF(COUNTIF($F$5:$F$2407,F1617)=1,"OK","Дубликат")
A1618: BONUS-L1-PLUS7 | B1618: 1 уровень | C1618: Призы не на абонементы | D1618: +7 дней к сроку действия абонемента | E1618: При покупке абонемента на 8 или 12 занятий | F1618: FW-L1-NQ8W2-X9RQZ | G1618: Не использован | K1618: 11 | L1618: =IF(COUNTIF($F$5:$F$2407,F1618)=1,"OK","Дубликат")
A1619: BONUS-L1-PLUS7 | B1619: 1 уровень | C1619: Призы не на абонементы | D1619: +7 дней к сроку действия абонемента | E1619: При покупке абонемента на 8 или 12 занятий | F1619: FW-L1-8H78M-6Q5MB | G1619: Не использован | K1619: 12 | L1619: =IF(COUNTIF($F$5:$F$2407,F1619)=1,"OK","Дубликат")
A1620: BONUS-L1-PLUS7 | B1620: 1 уровень | C1620: Призы не на абонементы | D1620: +7 дней к сроку действия абонемента | E1620: При покупке абонемента на 8 или 12 занятий | F1620: FW-L1-SVNMR-HWS6D | G1620: Не использован | K1620: 13 | L1620: =IF(COUNTIF($F$5:$F$2407,F1620)=1,"OK","Дубликат")
... A2207: BONUS-L1-FRIEND-15 | B2207: 1 уровень | C2207: Призы не на абонементы | D2207: Скидка 15% на второй абонемент для подруги | E2207: При покупке второго абонемента для подруги | F2207: FW-L1-H4G7L-5RXFL | G2207: Не использован | K2207: 200 | L2207: =IF(COUNTIF($F$5:$F$2407,F2207)=1,"OK","Дубликат")
A2208: BONUS-L2-PAIR | B2208: 2 уровень | C2208: Призы не на абонементы | D2208: Парный старт: закрытая цена на 2 абонемента | E2208: Покупка двух абонементов при совместном старте с подругой | F2208: FW-L2-YTZS8-S2VN9 | G2208: Использован | H2208: 46249.248 | I2208: Роман Михайлов, @RRedactor, +79035782777 | J2208: Выдан Telegram-ботом; Роман Михайлов, @RRedactor, +79035782777; сессия: session_a3d6310423b3 | K2208: 1 | L2208: =IF(COUNTIF($F$5:$F$2407,F2208)=1,"OK","Дубликат")
A2209: BONUS-L2-PAIR | B2209: 2 уровень | C2209: Призы не на абонементы | D2209: Парный старт: закрытая цена на 2 абонемента | E2209: Покупка двух абонементов при совместном старте с подругой | F2209: FW-L2-8AFXF-S4GFK | G2209: Использован | H2209: 46249.303 | I2209: Роман Михайлов, @RRedactor, +79035782777 | J2209: Выдан Telegram-ботом; Роман Михайлов, @RRedactor, +79035782777; сессия: session_cb9958d00971 | K2209: 2 | L2209: =IF(COUNTIF($F$5:$F$2407,F2209)=1,"OK","Дубликат")
A2210: BONUS-L2-PAIR | B2210: 2 уровень | C2210: Призы не на абонементы | D2210: Парный старт: закрытая цена на 2 абонемента | E2210: Покупка двух абонементов при совместном старте с подругой | F2210: FW-L2-ZH2NL-W68CE | G2210: Использован | H2210: 46249.309 | I2210: Роман Михайлов, @RRedactor, +79035782777 | J2210: Выдан Telegram-ботом; Роман Михайлов, @RRedactor, +79035782777; сессия: session_ebb7049ff715 | K2210: 3 | L2210: =IF(COUNTIF($F$5:$F$2407,F2210)=1,"OK","Дубликат")
A2211: BONUS-L2-PAIR | B2211: 2 уровень | C2211: Призы не на абонементы | D2211: Парный старт: закрытая цена на 2 абонемента | E2211: Покупка двух абонементов при совместном старте с подругой | F2211: FW-L2-9HPFX-D4N4R | G2211: Не использован | K2211: 4 | L2211: =IF(COUNTIF($F$5:$F$2407,F2211)=1,"OK","Дубликат")
A2212: BONUS-L2-PAIR | B2212: 2 уровень | C2212: Призы не на абонементы | D2212: Парный старт: закрытая цена на 2 абонемента | E2212: Покупка двух абонементов при совместном старте с подругой | F2212: FW-L2-55FN6-JGEWR | G2212: Не использован | K2212: 5 | L2212: =IF(COUNTIF($F$5:$F$2407,F2212)=1,"OK","Дубликат")
A2213: BONUS-L2-PAIR | B2213: 2 уровень | C2213: Призы не на абонементы | D2213: Парный старт: закрытая цена на 2 абонемента | E2213: Покупка двух абонементов при совместном старте с подругой | F2213: FW-L2-AF83V-GX4LN | G2213: Не использован | K2213: 6 | L2213: =IF(COUNTIF($F$5:$F$2407,F2213)=1,"OK","Дубликат")
A2214: BONUS-L2-PAIR | B2214: 2 уровень | C2214: Призы не на абонементы | D2214: Парный старт: закрытая цена на 2 абонемента | E2214: Покупка двух абонементов при совместном старте с подругой | F2214: FW-L2-ZVFD5-XN3BA | G2214: Не использован | K2214: 7 | L2214: =IF(COUNTIF($F$5:$F$2407,F2214)=1,"OK","Дубликат")
A2215: BONUS-L2-PAIR | B2215: 2 уровень | C2215: Призы не на абонементы | D2215: Парный старт: закрытая цена на 2 абонемента | E2215: Покупка двух абонементов при совместном старте с подругой | F2215: FW-L2-SHXY5-MU49F | G2215: Не использован | K2215: 8 | L2215: =IF(COUNTIF($F$5:$F$2407,F2215)=1,"OK","Дубликат")
...

Sheet Лиды Telegram
A1: Лиды и выдачи через Telegram-бота
A2: Контакты победителей (имя, фамилия, username, телефон) записываются для прямой связи менеджера и выдачи призов.
A4: Дата и время | B4: Telegram ref | C4: Телефон | D4: Username | E4: Имя | F4: Фамилия | G4: Код приза | H4: Приз | I4: Промокод | J4: Токен ref | K4: Сессия ref | L4: Статус | M4: Примечание
A5: 46249.246 | B5: 6110655759 | C5: '+79035782777 | D5: '@RRedactor | E5: Роман | F5: Михайлов | G5: BONUS-L1-PLUS7 | H5: '+7 дней к сроку действия абонемента | I5: FW-L1-72C38-M8J6W | J5: token_d846ca1c15d1 | K5: session_bfb6c5df5f6a | L5: Выдан | M5: Подписка подтверждена в Telegram
A6: 46249.248 | B6: 6110655759 | C6: '+79035782777 | D6: '@RRedactor | E6: Роман | F6: Михайлов | G6: BONUS-L2-PAIR | H6: Парный старт: закрытая цена на 2 абонемента | I6: FW-L2-YTZS8-S2VN9 | J6: token_1497d27fbac9 | K6: session_a3d6310423b3 | L6: Выдан | M6: Подписка подтверждена в Telegram
A7: 46249.258 | B7: 6110655759 | C7: '+79035782777 | D7: '@RRedactor | E7: Роман | F7: Михайлов | G7: SUB-L1-04-10 | H7: Скидка 10% на абонемент 4 занятия | I7: FW-L1-8LLQL-ZMXLC | J7: token_45709d48d270 | K7: session_461c9dbf1567 | L7: Выдан | M7: Подписка подтверждена в Telegram
A8: 46249.277 | B8: 6110655759 | C8: '+79035782777 | D8: '@RRedactor | E8: Роман | F8: Михайлов | G8: SUB-L1-04-10 | H8: Скидка 10% на абонемент 4 занятия | I8: FW-L1-TQ8VB-FWRDX | J8: token_aaa35ed98beb | K8: session_9d377af4d448 | L8: Выдан | M8: Подписка подтверждена в Telegram
A9: 46249.303 | B9: 6110655759 | C9: '+79035782777 | D9: '@RRedactor | E9: Роман | F9: Михайлов | G9: BONUS-L2-PAIR | H9: Парный старт: закрытая цена на 2 абонемента | I9: FW-L2-8AFXF-S4GFK | J9: token_4b38387c0df4 | K9: session_cb9958d00971 | L9: Выдан | M9: Подписка подтверждена в Telegram
A10: 46249.309 | B10: 6110655759 | C10: '+79035782777 | D10: '@RRedactor | E10: Роман | F10: Михайлов | G10: BONUS-L2-PAIR | H10: Парный старт: закрытая цена на 2 абонемента | I10: FW-L2-ZH2NL-W68CE | J10: token_4b4c07f71db4 | K10: session_ebb7049ff715 | L10: Выдан | M10: Подписка подтверждена в Telegram
